<?xml version="1.0" ?>
<robot name="my_robot" xmlns:xacro="http://www.ros.org/wiki/xacro">

  <!-- Macros for inertia calculations -->
  <xacro:macro name="box_inertia" params="m w h d">
    <inertial>
      <origin xyz="0 0 0" rpy="${pi/2} 0 ${pi/2}"/>
      <mass value="${m}"/>
      <inertia ixx="${(m/12) * (h*h + d*d)}" ixy="0.0" ixz="0.0" iyy="${(m/12) * (w*w + d*d)}" iyz="0.0" izz="${(m/12) * (w*w + h*h)}"/>
    </inertial>
  </xacro:macro>

  <xacro:macro name="cylinder_inertia" params="m r h">
    <inertial>
      <origin xyz="0 0 0" rpy="${pi/2} 0 0" />
      <mass value="${m}"/>
      <inertia ixx="${(m/12) * (3*r*r + h*h)}" ixy = "0" ixz = "0" iyy="${(m/12) * (3*r*r + h*h)}" iyz = "0" izz="${(m/2) * (r*r)}"/>
    </inertial>
  </xacro:macro>

  <xacro:macro name="sphere_inertia" params="m r">
    <inertial>
      <mass value="${m}"/>
      <inertia ixx="${(2/5) * m * (r*r)}" ixy="0.0" ixz="0.0" iyy="${(2/5) * m * (r*r)}" iyz="0.0" izz="${(2/5) * m * (r*r)}"/>
    </inertial>
  </xacro:macro>

  <!-- Material definitions -->
  <material name="grey">
    <color rgba="0.7 0.7 0.7 1" />
  </material>
  <material name="green">
    <color rgba="0 0.7 0 1" />
  </material>
  <material name="white">
    <color rgba="1 1 1 1" />
  </material>


  <!-- Base link definition -->
  <link name="base_link">
    <visual>
      <geometry>
        <box size="0.6 0.4 0.2" />
      </geometry>
      <origin xyz="0 0 0.1" rpy="0 0 0" />
      <material name="green" />
    </visual>
    <collision>
      <geometry>
        <box size="0.6 0.4 0.2" />
      </geometry>
      <origin xyz="0 0 0.1" rpy="0 0 0" />
      <material name="green" />
    </collision>
    <xacro:box_inertia m="5" w="0.6" d="0.4" h="0.2" />
  </link>

  <gazebo reference="base_link">
    <material>Gazebo/Orange</material>
  </gazebo>

  <!-- Lidar link -->
  <link name="lidar">
    <visual>
      <geometry>
        <cylinder radius="0.1" length="0.05" />
      </geometry>
      <origin xyz="0 0 0" rpy="0 0 0" />
      <material name="white" />
    </visual>
    <collision>
      <geometry>
        <box size="0.2 0.2 0.05" />
      </geometry>
      <origin xyz="0 0 0" rpy="0 0 0" />
        <material name="white" />
      </collision>
  </link>

  <!-- Wheel macros -->
<xacro:macro name="wheel" params="prefix x_reflect y_reflect">
    <link name="${prefix}_link">
      <visual>
        <origin xyz="0 0 0" rpy="${pi/2} 0 0"/>
        <geometry>
          <cylinder radius="${wheel_radius}" length="${wheel_width}"/>
        </geometry>
        <material name="Gray">
          <color rgba="0.5 0.5 0.5 1.0"/>
        </material>
      </visual>
      <collision>
        <origin xyz="0 0 0" rpy="${pi/2} 0 0"/>
        <geometry>
          <cylinder radius="${wheel_radius}" length="${wheel_width}"/>
        </geometry>
      </collision>
      <xacro:cylinder_inertia m="1" r="${wheel_radius}" h="${wheel_width}"/>
    </link>

    <joint name="${prefix}_joint" type="continuous">
      <parent link="base_link"/>
      <child link="${prefix}_link"/>
      <origin xyz="${-x_reflect*wheel_xoff} ${y_reflect*(base_width/2+wheel_ygap)} ${wheel_radius-wheel_zoff}" rpy="0 0 0"/>
      <axis xyz="0 1 0"/>
    </joint>
  </xacro:macro>

  <!-- Wheel dimensions and offsets -->
  <xacro:property name="wheel_radius" value="0.1" />
  <xacro:property name="wheel_width" value="0.05" />
  <xacro:property name="wheel_xoff" value="0.15" />
  <xacro:property name="wheel_ygap" value="0.025" />
  <xacro:property name="wheel_zoff" value="0.05" />
  <xacro:property name="base_width" value="0.4" />

  <!-- Left and right wheels -->
  <xacro:wheel prefix="left_wheel" x_reflect="1" y_reflect="1" />
  <xacro:wheel prefix="right_wheel" x_reflect="1" y_reflect="-1" />

  <gazebo reference="left_wheel_link">
    <material>Gazebo/Blue</material>
  </gazebo>

  <gazebo reference="right_wheel_link">
    <material>Gazebo/Blue</material>
  </gazebo>

  <!-- Caster wheel -->
  <link name="caster_wheel">
    <visual>
      <geometry>
        <sphere radius="0.05" />
      </geometry>
      <origin xyz= "0 0 0" rpy="0 0 0" />
      <material name="grey" />
    </visual>
    <collision>
      <geometry>
        <sphere radius="0.05" />
      </geometry>
      <origin xyz= "0 0 0" rpy="0 0 0" />
      <material name="grey" />
    </collision>
    <xacro:sphere_inertia m="0.5" r="0.05" />
  </link>


  <joint name="base_lidar_joint" type="fixed">
    <parent link="base_link" />
    <child link="lidar" />
    <origin xyz="0 0 0.225" rpy="0 0 0" />
  </joint>


  <joint name="base_caster_joint" type="fixed">
    <parent link="base_link" />
    <child link="caster_wheel" />
    <origin xyz="0.2 0 -0.025" rpy="0 0 0" />
  </joint>

  <!-- Gazebo plugin -->
  <gazebo>
    <plugin name='diff_drive' filename='libgazebo_ros_diff_drive.so'>
      <!-- wheels -->
      <left_joint>left_wheel_joint</left_joint>
      <right_joint>right_wheel_joint</right_joint>
      <!-- kinematics -->
      <wheel_separation>0.4</wheel_separation>
      <wheel_diameter>0.2</wheel_diameter>
      
      <publish_odom>true</publish_odom>
      <publish_odom_tf>false</publish_odom_tf>
      <publish_wheel_tf>true</publish_wheel_tf>
      <odometry_frame>odom</odometry_frame>
      <robot_base_frame>base_link</robot_base_frame>
    </plugin>
  </gazebo>

</robot>
